Workbook

Sheet vgsales
A1: Rank | B1: Name | C1: Platform | D1: Year | E1: Genre | F1: Publisher | G1: NA_Sales | H1: EU_Sales | I1: JP_Sales | J1: Other_Sales | K1: Global_Sales | N1: Platform | O1: Total Global Copies Sold
A2: 1 | B2: Wii Sports | C2: Wii | D2: 2006 | E2: Sports | F2: Nintendo | G2: 41.49 | H2: 29.02 | I2: 3.77 | J2: 8.46 | K2: 82.74 | N2: PS2 | O2: =SUMIF($C$2:$C$16599,N2,$K$2:$K$16599) -> 1255.64
A3: 2 | B3: Super Mario Bros. | C3: NES | D3: 1985 | E3: Platform | F3: Nintendo | G3: 29.08 | H3: 3.58 | I3: 6.81 | J3: 0.77 | K3: 40.24 | N3: X360 | O3: =SUMIF($C$2:$C$16599,N3,$K$2:$K$16599) -> 979.96
A4: 3 | B4: Mario Kart Wii | C4: Wii | D4: 2008 | E4: Racing | F4: Nintendo | G4: 15.85 | H4: 12.88 | I4: 3.79 | J4: 3.31 | K4: 35.82 | N4: PS3 | O4: =SUMIF($C$2:$C$16599,N4,$K$2:$K$16599) -> 957.84
A5: 4 | B5: Wii Sports Resort | C5: Wii | D5: 2009 | E5: Sports | F5: Nintendo | G5: 15.75 | H5: 11.01 | I5: 3.28 | J5: 2.96 | K5: 33 | N5: Wii | O5: =SUMIF($C$2:$C$16599,N5,$K$2:$K$16599) -> 926.71
A6: 5 | B6: Pokemon Red/Pokemon Blue | C6: GB | D6: 1996 | E6: Role-Playing | F6: Nintendo | G6: 11.27 | H6: 8.89 | I6: 10.22 | J6: 1 | K6: 31.37 | N6: DS | O6: =SUMIF($C$2:$C$16599,N6,$K$2:$K$16599) -> 822.49
A7: 6 | B7: Tetris | C7: GB | D7: 1989 | E7: Puzzle | F7: Nintendo | G7: 23.2 | H7: 2.26 | I7: 4.22 | J7: 0.58 | K7: 30.26 | N7: PS | O7: =SUMIF($C$2:$C$16599,N7,$K$2:$K$16599) -> 730.66
A8: 7 | B8: New Super Mario Bros. | C8: DS | D8: 2006 | E8: Platform | F8: Nintendo | G8: 11.38 | H8: 9.23 | I8: 6.5 | J8: 2.9 | K8: 30.01 | N8: GBA | O8: =SUMIF($C$2:$C$16599,N8,$K$2:$K$16599) -> 318.5
A9: 8 | B9: Wii Play | C9: Wii | D9: 2006 | E9: Misc | F9: Nintendo | G9: 14.03 | H9: 9.2 | I9: 2.93 | J9: 2.85 | K9: 29.02 | N9: PSP | O9: =SUMIF($C$2:$C$16599,N9,$K$2:$K$16599) -> 296.28
A10: 9 | B10: New Super Mario Bros. Wii | C10: Wii | D10: 2009 | E10: Platform | F10: Nintendo | G10: 14.59 | H10: 7.06 | I10: 4.7 | J10: 2.26 | K10: 28.62 | N10: PS4 | O10: =SUMIF($C$2:$C$16599,N10,$K$2:$K$16599) -> 278.1
A11: 10 | B11: Duck Hunt | C11: NES | D11: 1984 | E11: Shooter | F11: Nintendo | G11: 26.93 | H11: 0.63 | I11: 0.28 | J11: 0.47 | K11: 28.31 | N11: PC | O11: =SUMIF($C$2:$C$16599,N11,$K$2:$K$16599) -> 258.82
A12: 11 | B12: Nintendogs | C12: DS | D12: 2005 | E12: Simulation | F12: Nintendo | G12: 9.07 | H12: 11 | I12: 1.93 | J12: 2.75 | K12: 24.76 | N12: XB | O12: =SUMIF($C$2:$C$16599,N12,$K$2:$K$16599) -> 258.26
A13: 12 | B13: Mario Kart DS | C13: DS | D13: 2005 | E13: Racing | F13: Nintendo | G13: 9.81 | H13: 7.57 | I13: 4.13 | J13: 1.92 | K13: 23.42 | N13: GB | O13: =SUMIF($C$2:$C$16599,N13,$K$2:$K$16599) -> 255.45
... A19: 18 | B19: Grand Theft Auto: San Andreas | C19: PS2 | D19: 2004 | E19: Action | F19: Take-Two Interactive | G19: 9.43 | H19: 0.4 | I19: 0.41 | J19: 10.57 | K19: 20.81 | N19: XOne | O19: =SUMIF($C$2:$C$16599,N19,$K$2:$K$16599) -> 141.06
A20: 19 | B20: Super Mario World | C20: SNES | D20: 1990 | E20: Platform | F20: Nintendo | G20: 12.78 | H20: 3.75 | I20: 3.54 | J20: 0.55 | K20: 20.61 | N20: 2600 | O20: =SUMIF($C$2:$C$16599,N20,$K$2:$K$16599) -> 97.08
A21: 20 | B21: Brain Age: Train Your Brain in Minutes a Day | C21: DS | D21: 2005 | E21: Misc | F21: Nintendo | G21: 4.75 | H21: 9.26 | I21: 4.16 | J21: 2.05 | K21: 20.22 | N21: WiiU | O21: =SUMIF($C$2:$C$16599,N21,$K$2:$K$16599) -> 81.86
A22: 21 | B22: Pokemon Diamond/Pokemon Pearl | C22: DS | D22: 2006 | E22: Role-Playing | F22: Nintendo | G22: 6.42 | H22: 4.52 | I22: 6.04 | J22: 1.37 | K22: 18.36 | N22: PSV | O22: =SUMIF($C$2:$C$16599,N22,$K$2:$K$16599) -> 61.93
A23: 22 | B23: Super Mario Land | C23: GB | D23: 1989 | E23: Platform | F23: Nintendo | G23: 10.83 | H23: 2.71 | I23: 4.18 | J23: 0.42 | K23: 18.14 | N23: SAT | O23: =SUMIF($C$2:$C$16599,N23,$K$2:$K$16599) -> 33.59
A24: 23 | B24: Super Mario Bros. 3 | C24: NES | D24: 1988 | E24: Platform | F24: Nintendo | G24: 9.54 | H24: 3.44 | I24: 3.84 | J24: 0.46 | K24: 17.28 | N24: GEN | O24: =SUMIF($C$2:$C$16599,N24,$K$2:$K$16599) -> 28.36
A25: 24 | B25: Grand Theft Auto V | C25: X360 | D25: 2013 | E25: Action | F25: Take-Two Interactive | G25: 9.63 | H25: 5.31 | I25: 0.06 | J25: 1.38 | K25: 16.38 | N25: DC | O25: =SUMIF($C$2:$C$16599,N25,$K$2:$K$16599) -> 15.97
A26: 25 | B26: Grand Theft Auto: Vice City | C26: PS2 | D26: 2002 | E26: Action | F26: Take-Two Interactive | G26: 8.41 | H26: 5.49 | I26: 0.47 | J26: 1.78 | K26: 16.15 | N26: SCD | O26: =SUMIF($C$2:$C$16599,N26,$K$2:$K$16599) -> 1.87
A27: 26 | B27: Pokemon Ruby/Pokemon Sapphire | C27: GBA | D27: 2002 | E27: Role-Playing | F27: Nintendo | G27: 6.06 | H27: 3.9 | I27: 5.38 | J27: 0.5 | K27: 15.85 | N27: NG | O27: =SUMIF($C$2:$C$16599,N27,$K$2:$K$16599) -> 1.44
A28: 27 | B28: Pokemon Black/Pokemon White | C28: DS | D28: 2010 | E28: Role-Playing | F28: Nintendo | G28: 5.57 | H28: 3.28 | I28: 5.65 | J28: 0.82 | K28: 15.32 | N28: WS | O28: =SUMIF($C$2:$C$16599,N28,$K$2:$K$16599) -> 1.42
A29: 28 | B29: Brain Age 2: More Training in Minutes a Day | C29: DS | D29: 2005 | E29: Puzzle | F29: Nintendo | G29: 3.44 | H29: 5.36 | I29: 5.32 | J29: 1.18 | K29: 15.3 | N29: TG16 | O29: =SUMIF($C$2:$C$16599,N29,$K$2:$K$16599) -> 0.16
A30: 29 | B30: Gran Turismo 3: A-Spec | C30: PS2 | D30: 2001 | E30: Racing | F30: Sony Computer Entertainment | G30: 6.85 | H30: 5.09 | I30: 1.87 | J30: 1.16 | K30: 14.98 | N30: 3DO | O30: =SUMIF($C$2:$C$16599,N30,$K$2:$K$16599) -> 0.1
A31: 30 | B31: Call of Duty: Modern Warfare 3 | C31: X360 | D31: 2011 | E31: Shooter | F31: Activision | G31: 9.03 | H31: 4.28 | I31: 0.13 | J31: 1.32 | K31: 14.76 | N31: GG | O31: =SUMIF($C$2:$C$16599,N31,$K$2:$K$16599) -> 0.04
A32: 31 | B32: PokÃ©mon Yellow: Special Pikachu Edition | C32: GB | D32: 1998 | E32: Role-Playing | F32: Nintendo | G32: 5.89 | H32: 5.04 | I32: 3.12 | J32: 0.59 | K32: 14.64 | N32: PCFX | O32: =SUMIF($C$2:$C$16599,N32,$K$2:$K$16599) -> 0.03
A33: 32 | B33: Call of Duty: Black Ops | C33: X360 | D33: 2010 | E33: Shooter | F33: Activision | G33: 9.67 | H33: 3.73 | I33: 0.11 | J33: 1.13 | K33: 14.64
A34: 33 | B34: Pokemon X/Pokemon Y | C34: 3DS | D34: 2013 | E34: Role-Playing | F34: Nintendo | G34: 5.17 | H34: 4.05 | I34: 4.34 | J34: 0.79 | K34: 14.35
A35: 34 | B35: Call of Duty: Black Ops 3 | C35: PS4 | D35: 2015 | E35: Shooter | F35: Activision | G35: 5.77 | H35: 5.81 | I35: 0.35 | J35: 2.31 | K35: 14.24
A36: 35 | B36: Call of Duty: Black Ops II | C36: PS3 | D36: 2012 | E36: Shooter | F36: Activision | G36: 4.99 | H36: 5.88 | I36: 0.65 | J36: 2.52 | K36: 14.03
A37: 36 | B37: Call of Duty: Black Ops II | C37: X360 | D37: 2012 | E37: Shooter | F37: Activision | G37: 8.25 | H37: 4.3 | I37: 0.07 | J37: 1.12 | K37: 13.73
A38: 37 | B38: Call of Duty: Modern Warfare 2 | C38: X360 | D38: 2009 | E38: Shooter | F38: Activision | G38: 8.52 | H38: 3.63 | I38: 0.08 | J38: 1.29 | K38: 13.51
A39: 38 | B39: Call of Duty: Modern Warfare 3 | C39: PS3 | D39: 2011 | E39: Shooter | F39: Activision | G39: 5.54 | H39: 5.82 | I39: 0.49 | J39: 1.62 | K39: 13.46
A40: 39 | B40: Grand Theft Auto III | C40: PS2 | D40: 2001 | E40: Action | F40: Take-Two Interactive | G40: 6.99 | H40: 4.51 | I40: 0.3 | J40: 1.3 | K40: 13.1
A41: 40 | B41: Super Smash Bros. Brawl | C41: Wii | D41: 2008 | E41: Fighting | F41: Nintendo | G41: 6.75 | H41: 2.61 | I41: 2.66 | J41: 1.02 | K41: 13.04
A42: 41 | B42: Call of Duty: Black Ops | C42: PS3 | D42: 2010 | E42: Shooter | F42: Activision | G42: 5.98 | H42: 4.44 | I42: 0.48 | J42: 1.83 | K42: 12.73
A43: 42 | B43: Animal Crossing: Wild World | C43: DS | D43: 2005 | E43: Simulation | F43: Nintendo | G43: 2.55 | H43: 3.52 | I43: 5.33 | J43: 0.88 | K43: 12.27
A44: 43 | B44: Mario Kart 7 | C44: 3DS | D44: 2011 | E44: Racing | F44: Nintendo | G44: 4.74 | H44: 3.91 | I44: 2.67 | J44: 0.89 | K44: 12.21
... A90: 89 | B90: PokÃ©mon Platinum Version | C90: DS | D90: 2008 | E90: Role-Playing | F90: Nintendo | G90: 2.82 | H90: 1.78 | I90: 2.69 | J90: 0.55 | K90: 7.84
...

Sheet Sales by X
B2: Platform | C2: Total Global Copies Sold | E2: Year | F2: Total Global Copies Sold | H2: Genre | I2: Total Global Copies Sold | K2: Publisher | L2: Total Global Copies Sold
B3: PS2 | C3: 1255.64 | E3: 1980 | F3: =SUMIF(vgsales!$D$2:$D$16599,'Sales by X'!E3,vgsales!$K$2:$K$16599) -> 11.38 | H3: Sports | I3: =SUMIF(vgsales!$E$2:$E$16599,'Sales by X'!H3,vgsales!$K$2:$K$16599) -> 1330.93 | K3: Nintendo | L3: =SUMIF(vgsales!$F$2:$F$16599,'Sales by X'!K3,vgsales!$K$2:$K$16599) -> 1786.56
B4: X360 | C4: 979.96 | E4: 1981 | F4: =SUMIF(vgsales!$D$2:$D$16599,'Sales by X'!E4,vgsales!$K$2:$K$16599) -> 35.77 | H4: Platform | I4: =SUMIF(vgsales!$E$2:$E$16599,'Sales by X'!H4,vgsales!$K$2:$K$16599) -> 831.37 | K4: Microsoft Game Studios | L4: =SUMIF(vgsales!$F$2:$F$16599,'Sales by X'!K4,vgsales!$K$2:$K$16599) -> 245.79
B5: PS3 | C5: 957.84 | E5: 1982 | F5: =SUMIF(vgsales!$D$2:$D$16599,'Sales by X'!E5,vgsales!$K$2:$K$16599) -> 28.86 | H5: Racing | I5: =SUMIF(vgsales!$E$2:$E$16599,'Sales by X'!H5,vgsales!$K$2:$K$16599) -> 732.04 | K5: Take-Two Interactive | L5: =SUMIF(vgsales!$F$2:$F$16599,'Sales by X'!K5,vgsales!$K$2:$K$16599) -> 399.54
B6: Wii | C6: 926.71 | E6: 1983 | F6: =SUMIF(vgsales!$D$2:$D$16599,'Sales by X'!E6,vgsales!$K$2:$K$16599) -> 16.79 | H6: Sports | I6: =SUMIF(vgsales!$E$2:$E$16599,'Sales by X'!H6,vgsales!$K$2:$K$16599) -> 1330.93 | K6: Sony Computer Entertainment | L6: =SUMIF(vgsales!$F$2:$F$16599,'Sales by X'!K6,vgsales!$K$2:$K$16599) -> 607.5
B7: Wii | C7: 926.71 | E7: 1984 | F7: =SUMIF(vgsales!$D$2:$D$16599,'Sales by X'!E7,vgsales!$K$2:$K$16599) -> 50.36 | H7: Role-Playing | I7: =SUMIF(vgsales!$E$2:$E$16599,'Sales by X'!H7,vgsales!$K$2:$K$16599) -> 927.37 | K7: Activision | L7: =SUMIF(vgsales!$F$2:$F$16599,'Sales by X'!K7,vgsales!$K$2:$K$16599) -> 727.46
B8: DS | C8: 822.49 | E8: 1985 | F8: =SUMIF(vgsales!$D$2:$D$16599,'Sales by X'!E8,vgsales!$K$2:$K$16599) -> 53.94 | H8: Puzzle | I8: =SUMIF(vgsales!$E$2:$E$16599,'Sales by X'!H8,vgsales!$K$2:$K$16599) -> 244.95 | K8: Ubisoft | L8: =SUMIF(vgsales!$F$2:$F$16599,'Sales by X'!K8,vgsales!$K$2:$K$16599) -> 474.72
B9: PS | C9: 730.66 | E9: 1986 | F9: =SUMIF(vgsales!$D$2:$D$16599,'Sales by X'!E9,vgsales!$K$2:$K$16599) -> 37.07 | H9: Misc | I9: =SUMIF(vgsales!$E$2:$E$16599,'Sales by X'!H9,vgsales!$K$2:$K$16599) -> 809.96 | K9: Bethesda Softworks | L9: =SUMIF(vgsales!$F$2:$F$16599,'Sales by X'!K9,vgsales!$K$2:$K$16599) -> 82.14
B10: GBA | C10: 318.5 | E10: 1987 | F10: =SUMIF(vgsales!$D$2:$D$16599,'Sales by X'!E10,vgsales!$K$2:$K$16599) -> 21.74 | H10: Shooter | I10: =SUMIF(vgsales!$E$2:$E$16599,'Sales by X'!H10,vgsales!$K$2:$K$16599) -> 1037.37 | K10: Electronic Arts | L10: =SUMIF(vgsales!$F$2:$F$16599,'Sales by X'!K10,vgsales!$K$2:$K$16599) -> 1110.32
B11: PSP | C11: 296.28 | E11: 1988 | F11: =SUMIF(vgsales!$D$2:$D$16599,'Sales by X'!E11,vgsales!$K$2:$K$16599) -> 47.22 | H11: Simulation | I11: =SUMIF(vgsales!$E$2:$E$16599,'Sales by X'!H11,vgsales!$K$2:$K$16599) -> 392.2 | K11: Sega | L11: =SUMIF(vgsales!$F$2:$F$16599,'Sales by X'!K11,vgsales!$K$2:$K$16599) -> 272.99
B12: PS4 | C12: 278.1 | E12: 1989 | F12: =SUMIF(vgsales!$D$2:$D$16599,'Sales by X'!E12,vgsales!$K$2:$K$16599) -> 73.45 | H12: Action | I12: =SUMIF(vgsales!$E$2:$E$16599,'Sales by X'!H12,vgsales!$K$2:$K$16599) -> 1751.18 | K12: SquareSoft | L12: =SUMIF(vgsales!$F$2:$F$16599,'Sales by X'!K12,vgsales!$K$2:$K$16599) -> 57.65
B13: PC | C13: 258.82 | E13: 1990 | F13: =SUMIF(vgsales!$D$2:$D$16599,'Sales by X'!E13,vgsales!$K$2:$K$16599) -> 49.39 | H13: Fighting | I13: =SUMIF(vgsales!$E$2:$E$16599,'Sales by X'!H13,vgsales!$K$2:$K$16599) -> 448.91 | K13: Atari | L13: =SUMIF(vgsales!$F$2:$F$16599,'Sales by X'!K13,vgsales!$K$2:$K$16599) -> 157.22
B14: XB | C14: 258.26 | E14: 1991 | F14: =SUMIF(vgsales!$D$2:$D$16599,'Sales by X'!E14,vgsales!$K$2:$K$16599) -> 32.23 | H14: Adventure | I14: =SUMIF(vgsales!$E$2:$E$16599,'Sales by X'!H14,vgsales!$K$2:$K$16599) -> 239.04 | K14: 505 Games | L14: =SUMIF(vgsales!$F$2:$F$16599,'Sales by X'!K14,vgsales!$K$2:$K$16599) -> 55.91
B15: GB | C15: 255.45 | E15: 1992 | F15: =SUMIF(vgsales!$D$2:$D$16599,'Sales by X'!E15,vgsales!$K$2:$K$16599) -> 76.16 | H15: Strategy | I15: =SUMIF(vgsales!$E$2:$E$16599,'Sales by X'!H15,vgsales!$K$2:$K$16599) -> 175.12 | K15: Capcom | L15: =SUMIF(vgsales!$F$2:$F$16599,'Sales by X'!K15,vgsales!$K$2:$K$16599) -> 200.89
B16: NES | C16: 251.07 | E16: 1993 | F16: =SUMIF(vgsales!$D$2:$D$16599,'Sales by X'!E16,vgsales!$K$2:$K$16599) -> 45.98 | K16: GT Interactive | L16: =SUMIF(vgsales!$F$2:$F$16599,'Sales by X'!K16,vgsales!$K$2:$K$16599) -> 25.23
B17: 3DS | C17: 247.46 | E17: 1994 | F17: =SUMIF(vgsales!$D$2:$D$16599,'Sales by X'!E17,vgsales!$K$2:$K$16599) -> 79.17 | K17: Konami Digital Entertainment | L17: =SUMIF(vgsales!$F$2:$F$16599,'Sales by X'!K17,vgsales!$K$2:$K$16599) -> 283.64
B18: N64 | C18: 218.88 | E18: 1995 | F18: =SUMIF(vgsales!$D$2:$D$16599,'Sales by X'!E18,vgsales!$K$2:$K$16599) -> 88.11 | K18: Sony Computer Entertainment Europe | L18: =SUMIF(vgsales!$F$2:$F$16599,'Sales by X'!K18,vgsales!$K$2:$K$16599) -> 23.89
B19: SNES | C19: 200.05 | E19: 1996 | F19: =SUMIF(vgsales!$D$2:$D$16599,'Sales by X'!E19,vgsales!$K$2:$K$16599) -> 199.15 | K19: Square Enix | L19: =SUMIF(vgsales!$F$2:$F$16599,'Sales by X'!K19,vgsales!$K$2:$K$16599) -> 145.18
B20: GC | C20: 199.36 | E20: 1997 | F20: =SUMIF(vgsales!$D$2:$D$16599,'Sales by X'!E20,vgsales!$K$2:$K$16599) -> 200.98 | K20: LucasArts | L20: =SUMIF(vgsales!$F$2:$F$16599,'Sales by X'!K20,vgsales!$K$2:$K$16599) -> 87.34
B21: XOne | C21: 141.06 | E21: 1998 | F21: =SUMIF(vgsales!$D$2:$D$16599,'Sales by X'!E21,vgsales!$K$2:$K$16599) -> 256.47 | K21: Virgin Interactive | L21: =SUMIF(vgsales!$F$2:$F$16599,'Sales by X'!K21,vgsales!$K$2:$K$16599) -> 43.87
B22: 2600 | C22: 97.08 | E22: 1999 | F22: =SUMIF(vgsales!$D$2:$D$16599,'Sales by X'!E22,vgsales!$K$2:$K$16599) -> 251.27 | K22: Warner Bros. Interactive Entertainment | L22: =SUMIF(vgsales!$F$2:$F$16599,'Sales by X'!K22,vgsales!$K$2:$K$16599) -> 153.89
B23: WiiU | C23: 81.86 | E23: 2000 | F23: =SUMIF(vgsales!$D$2:$D$16599,'Sales by X'!E23,vgsales!$K$2:$K$16599) -> 201.56 | K23: Universal Interactive | L23: =SUMIF(vgsales!$F$2:$F$16599,'Sales by X'!K23,vgsales!$K$2:$K$16599) -> 17.77
B24: PSV | C24: 61.93 | E24: 2001 | F24: =SUMIF(vgsales!$D$2:$D$16599,'Sales by X'!E24,vgsales!$K$2:$K$16599) -> 331.47 | K24: Eidos Interactive | L24: =SUMIF(vgsales!$F$2:$F$16599,'Sales by X'!K24,vgsales!$K$2:$K$16599) -> 98.98
B25: SAT | C25: 33.59 | E25: 2002 | F25: =SUMIF(vgsales!$D$2:$D$16599,'Sales by X'!E25,vgsales!$K$2:$K$16599) -> 395.52 | K25: RedOctane | L25: =SUMIF(vgsales!$F$2:$F$16599,'Sales by X'!K25,vgsales!$K$2:$K$16599) -> 8.68
B26: GEN | C26: 28.36 | E26: 2003 | F26: =SUMIF(vgsales!$D$2:$D$16599,'Sales by X'!E26,vgsales!$K$2:$K$16599) -> 357.85 | K26: Vivendi Games | L26: =SUMIF(vgsales!$F$2:$F$16599,'Sales by X'!K26,vgsales!$K$2:$K$16599) -> 58.21
B27: DC | C27: 15.97 | E27: 2004 | F27: =SUMIF(vgsales!$D$2:$D$16599,'Sales by X'!E27,vgsales!$K$2:$K$16599) -> 419.31 | K27: Enix Corporation | L27: =SUMIF(vgsales!$F$2:$F$16599,'Sales by X'!K27,vgsales!$K$2:$K$16599) -> 33.74
B28: SCD | C28: 1.87 | E28: 2005 | F28: =SUMIF(vgsales!$D$2:$D$16599,'Sales by X'!E28,vgsales!$K$2:$K$16599) -> 459.94 | K28: Namco Bandai Games | L28: =SUMIF(vgsales!$F$2:$F$16599,'Sales by X'!K28,vgsales!$K$2:$K$16599) -> 254.09
B29: NG | C29: 1.44 | E29: 2006 | F29: =SUMIF(vgsales!$D$2:$D$16599,'Sales by X'!E29,vgsales!$K$2:$K$16599) -> 521.04 | K29: Palcom | L29: =SUMIF(vgsales!$F$2:$F$16599,'Sales by X'!K29,vgsales!$K$2:$K$16599) -> 4.17
B30: WS | C30: 1.42 | E30: 2007 | F30: =SUMIF(vgsales!$D$2:$D$16599,'Sales by X'!E30,vgsales!$K$2:$K$16599) -> 611.13 | K30: Hasbro Interactive | L30: =SUMIF(vgsales!$F$2:$F$16599,'Sales by X'!K30,vgsales!$K$2:$K$16599) -> 15.22
B31: TG16 | C31: 0.16 | E31: 2008 | F31: =SUMIF(vgsales!$D$2:$D$16599,'Sales by X'!E31,vgsales!$K$2:$K$16599) -> 678.9 | K31: THQ | L31: =SUMIF(vgsales!$F$2:$F$16599,'Sales by X'!K31,vgsales!$K$2:$K$16599) -> 340.77
B32: 3DO | C32: 0.1 | E32: 2009 | F32: =SUMIF(vgsales!$D$2:$D$16599,'Sales by X'!E32,vgsales!$K$2:$K$16599) -> 667.3 | K32: Fox Interactive | L32: =SUMIF(vgsales!$F$2:$F$16599,'Sales by X'!K32,vgsales!$K$2:$K$16599) -> 7.39
B33: GG | C33: 0.04 | E33: 2010 | F33: =SUMIF(vgsales!$D$2:$D$16599,'Sales by X'!E33,vgsales!$K$2:$K$16599) -> 600.45 | K33: Acclaim Entertainment | L33: =SUMIF(vgsales!$F$2:$F$16599,'Sales by X'!K33,vgsales!$K$2:$K$16599) -> 64.14
B34: PCFX | C34: 0.03 | E34: 2011 | F34: =SUMIF(vgsales!$D$2:$D$16599,'Sales by X'!E34,vgsales!$K$2:$K$16599) -> 515.99 | K34: MTV Games | L34: =SUMIF(vgsales!$F$2:$F$16599,'Sales by X'!K34,vgsales!$K$2:$K$16599) -> 20.97
E35: 2012 | F35: =SUMIF(vgsales!$D$2:$D$16599,'Sales by X'!E35,vgsales!$K$2:$K$16599) -> 363.54 | K35: Disney Interactive Studios | L35: =SUMIF(vgsales!$F$2:$F$16599,'Sales by X'!K35,vgsales!$K$2:$K$16599) -> 119.96
E36: 2013 | F36: =SUMIF(vgsales!$D$2:$D$16599,'Sales by X'!E36,vgsales!$K$2:$K$16599) -> 368.11 | K36: N/A | L36: =SUMIF(vgsales!$F$2:$F$16599,'Sales by X'!K36,vgsales!$K$2:$K$16599) -> 14.88
E37: 2014 | F37: =SUMIF(vgsales!$D$2:$D$16599,'Sales by X'!E37,vgsales!$K$2:$K$16599) -> 337.05 | K37: Majesco Entertainment | L37: =SUMIF(vgsales!$F$2:$F$16599,'Sales by X'!K37,vgsales!$K$2:$K$16599) -> 16.08
E38: 2015 | F38: =SUMIF(vgsales!$D$2:$D$16599,'Sales by X'!E38,vgsales!$K$2:$K$16599) -> 264.44 | K38: Codemasters | L38: =SUMIF(vgsales!$F$2:$F$16599,'Sales by X'!K38,vgsales!$K$2:$K$16599) -> 47.87
E39: 2016 | F39: =SUMIF(vgsales!$D$2:$D$16599,'Sales by X'!E39,vgsales!$K$2:$K$16599) -> 70.93 | K39: Red Orb | L39: =SUMIF(vgsales!$F$2:$F$16599,'Sales by X'!K39,vgsales!$K$2:$K$16599) -> 5.24
K40: Level 5 | L40: =SUMIF(vgsales!$F$2:$F$16599,'Sales by X'!K40,vgsales!$K$2:$K$16599) -> 12.17
K41: Arena Entertainment | L41: =SUMIF(vgsales!$F$2:$F$16599,'Sales by X'!K41,vgsales!$K$2:$K$16599) -> 4.72
...
