Workbook

Sheet vgsales
A1: Rank | B1: Name | C1: Platform | D1: Year | E1: Genre | F1: Publisher | G1: NA_Sales | H1: EU_Sales | I1: JP_Sales | J1: Other_Sales | K1: Global_Sales
A2: 1 | B2: Wii Sports | C2: Wii | D2: 2006 | E2: Sports | F2: Nintendo | G2: 41.49 | H2: 29.02 | I2: 3.77 | J2: 8.46 | K2: 82.74
A3: 2 | B3: Super Mario Bros. | C3: NES | D3: 1985 | E3: Platform | F3: Nintendo | G3: 29.08 | H3: 3.58 | I3: 6.81 | J3: 0.77 | K3: 40.24
A4: 3 | B4: Mario Kart Wii | C4: Wii | D4: 2008 | E4: Racing | F4: Nintendo | G4: 15.85 | H4: 12.88 | I4: 3.79 | J4: 3.31 | K4: 35.82
A5: 4 | B5: Wii Sports Resort | C5: Wii | D5: 2009 | E5: Sports | F5: Nintendo | G5: 15.75 | H5: 11.01 | I5: 3.28 | J5: 2.96 | K5: 33
A6: 5 | B6: Pokemon Red/Pokemon Blue | C6: GB | D6: 1996 | E6: Role-Playing | F6: Nintendo | G6: 11.27 | H6: 8.89 | I6: 10.22 | J6: 1 | K6: 31.37
A7: 6 | B7: Tetris | C7: GB | D7: 1989 | E7: Puzzle | F7: Nintendo | G7: 23.2 | H7: 2.26 | I7: 4.22 | J7: 0.58 | K7: 30.26
A8: 7 | B8: New Super Mario Bros. | C8: DS | D8: 2006 | E8: Platform | F8: Nintendo | G8: 11.38 | H8: 9.23 | I8: 6.5 | J8: 2.9 | K8: 30.01
A9: 8 | B9: Wii Play | C9: Wii | D9: 2006 | E9: Misc | F9: Nintendo | G9: 14.03 | H9: 9.2 | I9: 2.93 | J9: 2.85 | K9: 29.02
A10: 9 | B10: New Super Mario Bros. Wii | C10: Wii | D10: 2009 | E10: Platform | F10: Nintendo | G10: 14.59 | H10: 7.06 | I10: 4.7 | J10: 2.26 | K10: 28.62
A11: 10 | B11: Duck Hunt | C11: NES | D11: 1984 | E11: Shooter | F11: Nintendo | G11: 26.93 | H11: 0.63 | I11: 0.28 | J11: 0.47 | K11: 28.31
A12: 11 | B12: Nintendogs | C12: DS | D12: 2005 | E12: Simulation | F12: Nintendo | G12: 9.07 | H12: 11 | I12: 1.93 | J12: 2.75 | K12: 24.76
A13: 12 | B13: Mario Kart DS | C13: DS | D13: 2005 | E13: Racing | F13: Nintendo | G13: 9.81 | H13: 7.57 | I13: 4.13 | J13: 1.92 | K13: 23.42
... A90: 89 | B90: PokÃ©mon Platinum Version | C90: DS | D90: 2008 | E90: Role-Playing | F90: Nintendo | G90: 2.82 | H90: 1.78 | I90: 2.69 | J90: 0.55 | K90: 7.84
A91: 90 | B91: Pac-Man | C91: 2600 | D91: 1982 | E91: Puzzle | F91: Atari | G91: 7.28 | H91: 0.45 | I91: 0 | J91: 0.08 | K91: 7.81
A92: 91 | B92: Grand Theft Auto: Liberty City Stories | C92: PSP | D92: 2005 | E92: Action | F92: Take-Two Interactive | G92: 2.9 | H92: 2.83 | I92: 0.24 | J92: 1.75 | K92: 7.72
A93: 92 | B93: Super Mario Galaxy 2 | C93: Wii | D93: 2010 | E93: Platform | F93: Nintendo | G93: 3.66 | H93: 2.42 | I93: 0.98 | J93: 0.64 | K93: 7.69
A94: 93 | B94: Star Wars Battlefront (2015) | C94: PS4 | D94: 2015 | E94: Shooter | F94: Electronic Arts | G94: 2.93 | H94: 3.29 | I94: 0.22 | J94: 1.23 | K94: 7.67
A95: 94 | B95: Call of Duty: Advanced Warfare | C95: PS4 | D95: 2014 | E95: Shooter | F95: Activision | G95: 2.8 | H95: 3.3 | I95: 0.14 | J95: 1.37 | K95: 7.6
A96: 95 | B96: The Legend of Zelda: Ocarina of Time | C96: N64 | D96: 1998 | E96: Action | F96: Nintendo | G96: 4.1 | H96: 1.89 | I96: 1.45 | J96: 0.16 | K96: 7.6
A97: 96 | B97: Crash Bandicoot 2: Cortex Strikes Back | C97: PS | D97: 1997 | E97: Platform | F97: Sony Computer Entertainment | G97: 3.78 | H97: 2.17 | I97: 1.31 | J97: 0.31 | K97: 7.58
A98: 97 | B98: Super Mario Bros. 2 | C98: NES | D98: 1988 | E98: Platform | F98: Nintendo | G98: 5.39 | H98: 1.18 | I98: 0.7 | J98: 0.19 | K98: 7.46
A99: 98 | B99: Super Smash Bros. for Wii U and 3DS | C99: 3DS | D99: 2014 | E99: Fighting | F99: Nintendo | G99: 3.24 | H99: 1.35 | I99: 2.42 | J99: 0.43 | K99: 7.45
A100: 99 | B100: Call of Duty: World at War | C100: X360 | D100: 2008 | E100: Shooter | F100: Activision | G100: 4.79 | H100: 1.9 | I100: 0 | J100: 0.69 | K100: 7.37
A101: 100 | B101: Battlefield 3 | C101: X360 | D101: 2011 | E101: Shooter | F101: Electronic Arts | G101: 4.46 | H101: 2.13 | I101: 0.06 | J101: 0.69 | K101: 7.34
A102: 101 | B102: The Legend of Zelda: Twilight Princess | C102: Wii | D102: 2006 | E102: Action | F102: Nintendo | G102: 3.83 | H102: 2.19 | I102: 0.6 | J102: 0.7 | K102: 7.31
A103: 102 | B103: Call of Duty: Black Ops 3 | C103: XOne | D103: 2015 | E103: Shooter | F103: Activision | G103: 4.52 | H103: 2.09 | I103: 0.01 | J103: 0.67 | K103: 7.3
... A180: 179 | B180: Tomb Raider II | C180: PS | D180: 1997 | E180: Action | F180: Eidos Interactive | G180: 2.3 | H180: 2.46 | I180: 0.2 | J180: 0.28 | K180: 5.24
A181: 180 | B181: Madden NFL 2004 | C181: PS2 | D181: N/A | E181: Sports | F181: Electronic Arts | G181: 4.26 | H181: 0.26 | I181: 0.01 | J181: 0.71 | K181: 5.23
A182: 181 | B182: Dragon Quest VIII: Journey of the Cursed King | C182: PS2 | D182: 2004 | E182: Role-Playing | F182: Square Enix | G182: 0.65 | H182: 0.75 | I182: 3.61 | J182: 0.2 | K182: 5.21
A183: 182 | B183: Diablo III | C183: PC | D183: 2012 | E183: Role-Playing | F183: Activision | G183: 2.43 | H183: 2.15 | I183: 0 | J183: 0.62 | K183: 5.2
A184: 183 | B184: Super Mario Bros. 3 | C184: GBA | D184: 2003 | E184: Platform | F184: Nintendo | G184: 2.93 | H184: 1.25 | I184: 0.83 | J184: 0.2 | K184: 5.2
A185: 184 | B185: New Super Mario Bros. U | C185: WiiU | D185: 2012 | E185: Platform | F185: Nintendo | G185: 2.32 | H185: 1.3 | I185: 1.27 | J185: 0.31 | K185: 5.19
A186: 185 | B186: Super Mario Land 3: Wario Land | C186: GB | D186: 1994 | E186: Platform | F186: Nintendo | G186: 2.49 | H186: 0.98 | I186: 1.57 | J186: 0.15 | K186: 5.19
A187: 186 | B187: FIFA Soccer 13 | C187: X360 | D187: 2012 | E187: Action | F187: Electronic Arts | G187: 1.08 | H187: 3.48 | I187: 0.03 | J187: 0.58 | K187: 5.18
A188: 187 | B188: The Legend of Zelda: Phantom Hourglass | C188: DS | D188: 2007 | E188: Action | F188: Nintendo | G188: 1.9 | H188: 1.83 | I188: 0.95 | J188: 0.49 | K188: 5.17
A189: 188 | B189: Donkey Kong Country 2: Diddy's Kong Quest | C189: SNES | D189: 1995 | E189: Platform | F189: Nintendo | G189: 2.1 | H189: 0.74 | I189: 2.2 | J189: 0.11 | K189: 5.15
A190: 189 | B190: Tomodachi Life | C190: 3DS | D190: 2013 | E190: Simulation | F190: Nintendo | G190: 0.96 | H190: 2.02 | I190: 1.89 | J190: 0.28 | K190: 5.15
A191: 190 | B191: Mario & Sonic at the Olympic Games | C191: DS | D191: 2008 | E191: Sports | F191: Sega | G191: 1.64 | H191: 2.48 | I191: 0.44 | J191: 0.58 | K191: 5.14
A192: 191 | B192: Medal of Honor: Rising Sun | C192: PS2 | D192: 2003 | E192: Shooter | F192: Electronic Arts | G192: 1.98 | H192: 2.23 | I192: 0.13 | J192: 0.8 | K192: 5.13
...

Sheet Charts
A1: Platform | B1: Total Global Copies Sold | N1: Genre | O1: Total Global Copies Sold
A2: PS2 | B2: =SUMIF(vgsales!$C$2:$C$16599,A2,vgsales!$K$2:$K$16599) -> 1255.64 | N2: Sports | O2: =SUMIF(vgsales!$E$2:$E$16599,Charts!N2,vgsales!$K$2:$K$16599) -> 1330.93
A3: X360 | B3: =SUMIF(vgsales!$C$2:$C$16599,A3,vgsales!$K$2:$K$16599) -> 979.96 | N3: Platform | O3: =SUMIF(vgsales!$E$2:$E$16599,Charts!N3,vgsales!$K$2:$K$16599) -> 831.37
A4: PS3 | B4: =SUMIF(vgsales!$C$2:$C$16599,A4,vgsales!$K$2:$K$16599) -> 957.84 | N4: Racing | O4: =SUMIF(vgsales!$E$2:$E$16599,Charts!N4,vgsales!$K$2:$K$16599) -> 732.04
A5: Wii | B5: =SUMIF(vgsales!$C$2:$C$16599,A5,vgsales!$K$2:$K$16599) -> 926.71 | N5: Sports | O5: =SUMIF(vgsales!$E$2:$E$16599,Charts!N5,vgsales!$K$2:$K$16599) -> 1330.93
A6: DS | B6: =SUMIF(vgsales!$C$2:$C$16599,A6,vgsales!$K$2:$K$16599) -> 822.49 | N6: Role-Playing | O6: =SUMIF(vgsales!$E$2:$E$16599,Charts!N6,vgsales!$K$2:$K$16599) -> 927.37
A7: PS | B7: =SUMIF(vgsales!$C$2:$C$16599,A7,vgsales!$K$2:$K$16599) -> 730.66 | N7: Puzzle | O7: =SUMIF(vgsales!$E$2:$E$16599,Charts!N7,vgsales!$K$2:$K$16599) -> 244.95
A8: GBA | B8: =SUMIF(vgsales!$C$2:$C$16599,A8,vgsales!$K$2:$K$16599) -> 318.5 | N8: Misc | O8: =SUMIF(vgsales!$E$2:$E$16599,Charts!N8,vgsales!$K$2:$K$16599) -> 809.96
A9: PSP | B9: =SUMIF(vgsales!$C$2:$C$16599,A9,vgsales!$K$2:$K$16599) -> 296.28 | N9: Shooter | O9: =SUMIF(vgsales!$E$2:$E$16599,Charts!N9,vgsales!$K$2:$K$16599) -> 1037.37
A10: PS4 | B10: =SUMIF(vgsales!$C$2:$C$16599,A10,vgsales!$K$2:$K$16599) -> 278.1 | N10: Simulation | O10: =SUMIF(vgsales!$E$2:$E$16599,Charts!N10,vgsales!$K$2:$K$16599) -> 392.2
A11: PC | B11: =SUMIF(vgsales!$C$2:$C$16599,A11,vgsales!$K$2:$K$16599) -> 258.82 | N11: Action | O11: =SUMIF(vgsales!$E$2:$E$16599,Charts!N11,vgsales!$K$2:$K$16599) -> 1751.18
A12: XB | B12: =SUMIF(vgsales!$C$2:$C$16599,A12,vgsales!$K$2:$K$16599) -> 258.26 | N12: Fighting | O12: =SUMIF(vgsales!$E$2:$E$16599,Charts!N12,vgsales!$K$2:$K$16599) -> 448.91
A13: GB | B13: =SUMIF(vgsales!$C$2:$C$16599,A13,vgsales!$K$2:$K$16599) -> 255.45 | N13: Adventure | O13: =SUMIF(vgsales!$E$2:$E$16599,Charts!N13,vgsales!$K$2:$K$16599) -> 239.04
A14: NES | B14: =SUMIF(vgsales!$C$2:$C$16599,A14,vgsales!$K$2:$K$16599) -> 251.07 | N14: Strategy | O14: =SUMIF(vgsales!$E$2:$E$16599,Charts!N14,vgsales!$K$2:$K$16599) -> 175.12
A15: 3DS | B15: =SUMIF(vgsales!$C$2:$C$16599,A15,vgsales!$K$2:$K$16599) -> 247.46
A16: N64 | B16: =SUMIF(vgsales!$C$2:$C$16599,A16,vgsales!$K$2:$K$16599) -> 218.88
A17: SNES | B17: =SUMIF(vgsales!$C$2:$C$16599,A17,vgsales!$K$2:$K$16599) -> 200.05
A18: GC | B18: =SUMIF(vgsales!$C$2:$C$16599,A18,vgsales!$K$2:$K$16599) -> 199.36
A19: XOne | B19: =SUMIF(vgsales!$C$2:$C$16599,A19,vgsales!$K$2:$K$16599) -> 141.06
A20: 2600 | B20: =SUMIF(vgsales!$C$2:$C$16599,A20,vgsales!$K$2:$K$16599) -> 97.08
A21: WiiU | B21: =SUMIF(vgsales!$C$2:$C$16599,A21,vgsales!$K$2:$K$16599) -> 81.86
A22: PSV | B22: =SUMIF(vgsales!$C$2:$C$16599,A22,vgsales!$K$2:$K$16599) -> 61.93
A23: SAT | B23: =SUMIF(vgsales!$C$2:$C$16599,A23,vgsales!$K$2:$K$16599) -> 33.59
A24: GEN | B24: =SUMIF(vgsales!$C$2:$C$16599,A24,vgsales!$K$2:$K$16599) -> 28.36
A25: DC | B25: =SUMIF(vgsales!$C$2:$C$16599,A25,vgsales!$K$2:$K$16599) -> 15.97
A26: SCD | B26: =SUMIF(vgsales!$C$2:$C$16599,A26,vgsales!$K$2:$K$16599) -> 1.87
A27: NG | B27: =SUMIF(vgsales!$C$2:$C$16599,A27,vgsales!$K$2:$K$16599) -> 1.44
A28: WS | B28: =SUMIF(vgsales!$C$2:$C$16599,A28,vgsales!$K$2:$K$16599) -> 1.42
A29: TG16 | B29: =SUMIF(vgsales!$C$2:$C$16599,A29,vgsales!$K$2:$K$16599) -> 0.16
A30: 3DO | B30: =SUMIF(vgsales!$C$2:$C$16599,A30,vgsales!$K$2:$K$16599) -> 0.1
A31: GG | B31: =SUMIF(vgsales!$C$2:$C$16599,A31,vgsales!$K$2:$K$16599) -> 0.04
A32: PCFX | B32: =SUMIF(vgsales!$C$2:$C$16599,A32,vgsales!$K$2:$K$16599) -> 0.03
A36: Year | B36: Total Global Copies Sold
A37: 1980 | B37: =SUMIF(vgsales!$D$2:$D$16599,Charts!A37,vgsales!$K$2:$K$16599) -> 11.38
A38: 1981 | B38: =SUMIF(vgsales!$D$2:$D$16599,Charts!A38,vgsales!$K$2:$K$16599) -> 35.77
A39: 1982 | B39: =SUMIF(vgsales!$D$2:$D$16599,Charts!A39,vgsales!$K$2:$K$16599) -> 28.86
A40: 1983 | B40: =SUMIF(vgsales!$D$2:$D$16599,Charts!A40,vgsales!$K$2:$K$16599) -> 16.79
A41: 1984 | B41: =SUMIF(vgsales!$D$2:$D$16599,Charts!A41,vgsales!$K$2:$K$16599) -> 50.36
A42: 1985 | B42: =SUMIF(vgsales!$D$2:$D$16599,Charts!A42,vgsales!$K$2:$K$16599) -> 53.94
A43: 1986 | B43: =SUMIF(vgsales!$D$2:$D$16599,Charts!A43,vgsales!$K$2:$K$16599) -> 37.07
...
